Workbook
Name 仮払金額: 記入例!$AJ$6
Name 仮払金額: '精算書（交通費）'!$AI$6
Name 仮払金額: #REF!
Name 会社名: 記入例!$R$4
Name 会社名: '精算書（交通費）'!$Q$4
Name 会社名: #REF!
Name 合計金額: 記入例!#REF!
Name 合計金額: '精算書（交通費）'!#REF!
Name 合計金額: #REF!
Name 精算区分: 記入例!$Z$4
Name 精算区分: '精算書（交通費）'!$Y$4
Name 精算区分: #REF!
Name 部門: 部門!$A$3:$A$14

Sheet 精算書（交通費）
D1: 精算書（交通費） | AQ1: =IF(会社名="サン・ジャパン", "JP", IF(会社名="SJホールディングス", "HD", ""))
A2: ㈱リーディングソフト
A3: 決裁承認 | D3: 検印 | G3: 申請者 | J3: 部門 | N3: 社員番号 | S3: 氏名 | AG3: 作成日
J4: カスタマサポートエンジニアリング部 | N4: 1073 | S4: 玉城基文 | AD4: 印 | AG4: =NOW() -> 46234.419
A8: 発生日 | D8: 目的・訪問先 | K8: 交通手段 | N8: 経路 | AA8: 片道金額 （IC運賃） | AD8: 往復 | AF8: 小計 | AJ8: 領収証No.
A9: 46212 | D9: 目的 | F9: その他会社業務 | K9: 電車・バス | N9: 駅名 | P9: 八千代緑が丘 | S9: ～ | T9: 日本橋 | W9: ～ | X9: 青物横丁 | AA9: 1095 | AD9: ● | AF9: =IF(AND(K9="電車・バス", AD9="●"), AA9*2, IF(OR(K9="電車・バス",K9= "タクシー"), AA9, 0)) -> 2190
D10: 訪問先 | F10: 本社 | N10: 路線名 | P10: 東葉高速 | U10: ～ | V10: 京急本線
A11: 46226 | D11: 目的 | F11: その他会社業務 | K11: 電車・バス | N11: 駅名 | P11: 八千代緑が丘 | S11: ～ | T11: 日本橋 | W11: ～ | X11: 青物横丁 | AA11: 1095 | AD11: ● | AF11: =IF(AND(K11="電車・バス", AD11="●"), AA11*2, IF(OR(K11="電車・バス",K11= "タクシー"), AA11, 0)) -> 2190
D12: 訪問先 | F12: 本社 | N12: 路線名 | P12: 東葉高速 | U12: ～ | V12: 京急本線
D13: 目的 | K13: 電車・バス | N13: 駅名 | S13: ～ | W13: ～ | AF13: =IF(AND(K13="電車・バス", AD13="●"), AA13*2, IF(OR(K13="電車・バス",K13= "タクシー"), AA13, 0)) -> 0
D14: 訪問先 | N14: 路線名 | U14: ～
D15: 目的 | K15: 電車・バス | N15: 駅名 | S15: ～ | W15: ～ | AF15: =IF(AND(K15="電車・バス", AD15="●"), AA15*2, IF(OR(K15="電車・バス",K15= "タクシー"), AA15, 0)) -> 0
D16: 訪問先 | N16: 路線名 | U16: ～
D17: 目的 | K17: 電車・バス | N17: 駅名 | S17: ～ | W17: ～ | AF17: =IF(AND(K17="電車・バス", AD17="●"), AA17*2, IF(OR(K17="電車・バス",K17= "タクシー"), AA17, 0)) -> 0
D18: 訪問先 | N18: 路線名 | U18: ～
D19: 目的 | K19: 電車・バス | N19: 駅名 | S19: ～ | W19: ～ | AF19: =IF(AND(K19="電車・バス", AD19="●"), AA19*2, IF(OR(K19="電車・バス",K19= "タクシー"), AA19, 0)) -> 0
D20: 訪問先 | N20: 路線名 | U20: ～
D21: 目的 | K21: 電車・バス | N21: 駅名 | S21: ～ | W21: ～ | AF21: =IF(AND(K21="電車・バス", AD21="●"), AA21*2, IF(OR(K21="電車・バス",K21= "タクシー"), AA21, 0)) -> 0
D22: 訪問先 | N22: 路線名 | U22: ～
D23: 目的 | K23: 電車・バス | N23: 駅名 | S23: ～ | W23: ～ | AF23: =IF(AND(K23="電車・バス", AD23="●"), AA23*2, IF(OR(K23="電車・バス",K23= "タクシー"), AA23, 0)) -> 0
D24: 訪問先 | N24: 路線名 | U24: ～
D25: 目的 | K25: 電車・バス | N25: 駅名 | S25: ～ | W25: ～ | AF25: =IF(AND(K25="電車・バス", AD25="●"), AA25*2, IF(OR(K25="電車・バス",K25= "タクシー"), AA25, 0)) -> 0
D26: 訪問先 | N26: 路線名 | U26: ～ | BI26: ・
D27: 目的 | K27: 電車・バス | N27: 駅名 | S27: ～ | W27: ～ | AF27: =IF(AND(K27="電車・バス", AD27="●"), AA27*2, IF(OR(K27="電車・バス",K27= "タクシー"), AA27, 0)) -> 0
D28: 訪問先 | N28: 路線名 | U28: ～
D29: 目的 | K29: 電車・バス | N29: 駅名 | S29: ～ | W29: ～ | AF29: =IF(AND(K29="電車・バス", AD29="●"), AA29*2, IF(OR(K29="電車・バス",K29= "タクシー"), AA29, 0)) -> 0
D30: 訪問先 | N30: 路線名 | U30: ～
D31: 目的 | K31: 電車・バス | N31: 駅名 | S31: ～ | W31: ～ | AF31: =IF(AND(K31="電車・バス", AD31="●"), AA31*2, IF(OR(K31="電車・バス",K31= "タクシー"), AA31, 0)) -> 0
D32: 訪問先 | N32: 路線名 | U32: ～
D33: 目的 | K33: 電車・バス | N33: 駅名 | S33: ～ | W33: ～ | AF33: =IF(AND(K33="電車・バス", AD33="●"), AA33*2, IF(OR(K33="電車・バス",K33= "タクシー"), AA33, 0)) -> 0
D34: 訪問先 | N34: 路線名 | U34: ～
D35: 目的 | K35: 電車・バス | N35: 駅名 | S35: ～ | W35: ～ | AF35: =IF(AND(K35="電車・バス", AD35="●"), AA35*2, IF(OR(K35="電車・バス",K35= "タクシー"), AA35, 0)) -> 0
D36: 訪問先 | N36: 路線名 | U36: ～
D37: 目的 | K37: 電車・バス | N37: 駅名 | S37: ～ | W37: ～ | AF37: =IF(AND(K37="電車・バス", AD37="●"), AA37*2, IF(OR(K37="電車・バス",K37= "タクシー"), AA37, 0)) -> 0
D38: 訪問先 | N38: 路線名 | U38: ～
D39: 目的 | K39: 電車・バス | N39: 駅名 | S39: ～ | W39: ～ | AF39: =IF(AND(K39="電車・バス", AD39="●"), AA39*2, IF(OR(K39="電車・バス",K39= "タクシー"), AA39, 0)) -> 0
D40: 訪問先 | N40: 路線名 | U40: ～
D41: 目的 | K41: 電車・バス | N41: 駅名 | S41: ～ | W41: ～ | AF41: =IF(AND(K41="電車・バス", AD41="●"), AA41*2, IF(OR(K41="電車・バス",K41= "タクシー"), AA41, 0)) -> 0
D42: 訪問先 | N42: 路線名 | U42: ～
D43: 目的 | K43: 電車・バス | N43: 駅名 | S43: ～ | W43: ～ | AF43: =IF(AND(K43="電車・バス", AD43="●"), AA43*2, IF(OR(K43="電車・バス",K43= "タクシー"), AA43, 0)) -> 0
...

Sheet 記入例
E1: 記入要領：精算書（交通費） | AR1: =IF(会社名="サン・ジャパン", "JP", IF(会社名="SJホールディングス", "HD", ""))
B2: ※黄色の欄だけ入力してください
B3: 決裁承認 | E3: 検印 | H3: 申請者 | K3: 部門 | O3: 社員番号 | T3: 氏名 | AH3: 作成日
K4: 財務経理部 | O4: 11 | T4: ○○ ●● | AE4: 印 | AH4: =NOW() -> 46234.419
B8: 発生日 | E8: 目的・訪問先 | L8: 交通手段 | O8: 経路 | AB8: 片道金額 | AE8: 往復 | AG8: 小計 | AK8: 領収証No.
B9: 39066 | E9: 目的 | G9: 研修・セミナー参加 | L9: 電車・バス | O9: 駅名 | Q9: 品川シーサイド | T9: =IF(AE9="","⇒","⇔") -> ⇔ | U9: 東京 | X9: =IF(AE9="","⇒","⇔") -> ⇔ | AB9: 360 | AE9: ● | AG9: =IF(AND(L9="電車・バス", AE9="●"), AB9*2, IF(OR(L9="電車・バス",L9= "タクシー"), AB9, 0)) -> 720
E10: 訪問先 | G10: 新日本監査法人 | O10: 路線名 | Q10: りんかい線・ＪＲ | V10: =IF(AE9="","⇒","⇔") -> ⇔
B11: 39069 | E11: 目的 | G11: 深夜帰宅 | L11: タクシー | O11: 駅名 | Q11: 品川シーサイド | T11: =IF(AE11="","⇒","⇔") -> ⇒ | U11: 自宅 | X11: =IF(AE11="","⇒","⇔") -> ⇒ | AB11: 5000 | AG11: =IF(AND(L11="電車・バス", AE11="●"), AB11*2, IF(OR(L11="電車・バス",L11= "タクシー"), AB11, 0)) -> 5000 | AK11: 1
E12: 訪問先 | G12: 自宅 | O12: 路線名 | V12: =IF(AE11="","⇒","⇔") -> ⇒
E13: 目的 | O13: 駅名 | T13: =IF(AE13="","⇒","⇔") -> ⇒ | X13: =IF(AE13="","⇒","⇔") -> ⇒ | AG13: =IF(AND(L13="電車・バス", AE13="●"), AB13*2, IF(OR(L13="電車・バス",L13= "タクシー"), AB13, 0)) -> 0
E14: 訪問先 | O14: 路線名 | V14: =IF(AE13="","⇒","⇔") -> ⇒
E15: 目的 | O15: 駅名 | T15: =IF(AE15="","⇒","⇔") -> ⇒ | X15: =IF(AE15="","⇒","⇔") -> ⇒ | AG15: =IF(AND(L15="電車・バス", AE15="●"), AB15*2, IF(OR(L15="電車・バス",L15= "タクシー"), AB15, 0)) -> 0
E16: 訪問先 | O16: 路線名 | V16: =IF(AE15="","⇒","⇔") -> ⇒
E17: 目的 | O17: 駅名 | T17: =IF(AE17="","⇒","⇔") -> ⇒ | X17: =IF(AE17="","⇒","⇔") -> ⇒ | AG17: =IF(AND(L17="電車・バス", AE17="●"), AB17*2, IF(OR(L17="電車・バス",L17= "タクシー"), AB17, 0)) -> 0
E18: 訪問先 | O18: 路線名 | V18: =IF(AE17="","⇒","⇔") -> ⇒
E19: 目的 | O19: 駅名 | T19: =IF(AE19="","⇒","⇔") -> ⇒ | X19: =IF(AE19="","⇒","⇔") -> ⇒ | AG19: =IF(AND(L19="電車・バス", AE19="●"), AB19*2, IF(OR(L19="電車・バス",L19= "タクシー"), AB19, 0)) -> 0
E20: 訪問先 | O20: 路線名 | V20: =IF(AE19="","⇒","⇔") -> ⇒
E21: 目的 | O21: 駅名 | T21: =IF(AE21="","⇒","⇔") -> ⇒ | X21: =IF(AE21="","⇒","⇔") -> ⇒ | AG21: =IF(AND(L21="電車・バス", AE21="●"), AB21*2, IF(OR(L21="電車・バス",L21= "タクシー"), AB21, 0)) -> 0
E22: 訪問先 | O22: 路線名 | V22: =IF(AE21="","⇒","⇔") -> ⇒
E23: 目的 | O23: 駅名 | T23: =IF(AE23="","⇒","⇔") -> ⇒ | X23: =IF(AE23="","⇒","⇔") -> ⇒ | AG23: =IF(AND(L23="電車・バス", AE23="●"), AB23*2, IF(OR(L23="電車・バス",L23= "タクシー"), AB23, 0)) -> 0
E24: 訪問先 | O24: 路線名 | V24: =IF(AE23="","⇒","⇔") -> ⇒
E25: 目的 | O25: 駅名 | T25: =IF(AE25="","⇒","⇔") -> ⇒ | X25: =IF(AE25="","⇒","⇔") -> ⇒ | AG25: =IF(AND(L25="電車・バス", AE25="●"), AB25*2, IF(OR(L25="電車・バス",L25= "タクシー"), AB25, 0)) -> 0
E26: 訪問先 | O26: 路線名 | V26: =IF(AE25="","⇒","⇔") -> ⇒
E27: 目的 | O27: 駅名 | T27: =IF(AE27="","⇒","⇔") -> ⇒ | X27: =IF(AE27="","⇒","⇔") -> ⇒ | AG27: =IF(AND(L27="電車・バス", AE27="●"), AB27*2, IF(OR(L27="電車・バス",L27= "タクシー"), AB27, 0)) -> 0
E28: 訪問先 | O28: 路線名 | V28: =IF(AE27="","⇒","⇔") -> ⇒
E29: 目的 | O29: 駅名 | T29: =IF(AE29="","⇒","⇔") -> ⇒ | X29: =IF(AE29="","⇒","⇔") -> ⇒ | AG29: =IF(AND(L29="電車・バス", AE29="●"), AB29*2, IF(OR(L29="電車・バス",L29= "タクシー"), AB29, 0)) -> 0
E30: 訪問先 | O30: 路線名 | V30: =IF(AE29="","⇒","⇔") -> ⇒
E31: 目的 | O31: 駅名 | T31: =IF(AE31="","⇒","⇔") -> ⇒ | X31: =IF(AE31="","⇒","⇔") -> ⇒ | AG31: =IF(AND(L31="電車・バス", AE31="●"), AB31*2, IF(OR(L31="電車・バス",L31= "タクシー"), AB31, 0)) -> 0
E32: 訪問先 | O32: 路線名 | V32: =IF(AE31="","⇒","⇔") -> ⇒
E33: 目的 | O33: 駅名 | T33: =IF(AE33="","⇒","⇔") -> ⇒ | X33: =IF(AE33="","⇒","⇔") -> ⇒ | AG33: =IF(AND(L33="電車・バス", AE33="●"), AB33*2, IF(OR(L33="電車・バス",L33= "タクシー"), AB33, 0)) -> 0
E34: 訪問先 | O34: 路線名 | V34: =IF(AE33="","⇒","⇔") -> ⇒
E35: 目的 | O35: 駅名 | T35: =IF(AE35="","⇒","⇔") -> ⇒ | X35: =IF(AE35="","⇒","⇔") -> ⇒ | AG35: =IF(AND(L35="電車・バス", AE35="●"), AB35*2, IF(OR(L35="電車・バス",L35= "タクシー"), AB35, 0)) -> 0
E36: 訪問先 | O36: 路線名 | V36: =IF(AE35="","⇒","⇔") -> ⇒
E37: 目的 | O37: 駅名 | T37: =IF(AE37="","⇒","⇔") -> ⇒ | X37: =IF(AE37="","⇒","⇔") -> ⇒ | AG37: =IF(AND(L37="電車・バス", AE37="●"), AB37*2, IF(OR(L37="電車・バス",L37= "タクシー"), AB37, 0)) -> 0
E38: 訪問先 | O38: 路線名 | V38: =IF(AE37="","⇒","⇔") -> ⇒
E39: 目的 | O39: 駅名 | T39: =IF(AE39="","⇒","⇔") -> ⇒ | X39: =IF(AE39="","⇒","⇔") -> ⇒ | AG39: =IF(AND(L39="電車・バス", AE39="●"), AB39*2, IF(OR(L39="電車・バス",L39= "タクシー"), AB39, 0)) -> 0
E40: 訪問先 | O40: 路線名 | V40: =IF(AE39="","⇒","⇔") -> ⇒
E41: 目的 | O41: 駅名 | T41: =IF(AE41="","⇒","⇔") -> ⇒ | X41: =IF(AE41="","⇒","⇔") -> ⇒ | AG41: =IF(AND(L41="電車・バス", AE41="●"), AB41*2, IF(OR(L41="電車・バス",L41= "タクシー"), AB41, 0)) -> 0
E42: 訪問先 | O42: 路線名 | V42: =IF(AE41="","⇒","⇔") -> ⇒
E43: 目的 | O43: 駅名 | T43: =IF(AE43="","⇒","⇔") -> ⇒ | X43: =IF(AE43="","⇒","⇔") -> ⇒ | AG43: =IF(AND(L43="電車・バス", AE43="●"), AB43*2, IF(OR(L43="電車・バス",L43= "タクシー"), AB43, 0)) -> 0
...

Sheet 集計シート
A1: 個人精算区分 | B1: 名前 | C1: 社員番号 | D1: 負担部門 | E1: 発生日 | F1: 開発区分 | G1: 勘定項目1 | H1: 勘定項目2 | I1: 勘定項目3 | J1: 勘定項目 | K1: 補助項目1 | L1: 補助項目2 | M1: 補助項目 | N1: 金額 | O1: 支払先 | P1: 税区分 | Q1: 摘要 | R1: プロジェクトコード:名称 | S1: ファイル名
A2: 交通費 | B2: ='精算書（交通費）'!S4 -> 玉城基文 | C2: ='精算書（交通費）'!N4 -> 1073 | D2: ='精算書（交通費）'!J4 -> カスタマサポートエンジニアリング部 | E2: =MAX('精算書（交通費）'!A:A) -> 46226 | F2: =IF(D2="管理部","",IF(D2="営業部","",IF(D2="取締役会","","製造部門"))) -> 製造部門 | I2: 旅費交通費 | J2: =IF(F2<>"","[製]"&I2,I2) -> [製]旅費交通費 | M2: =B2 -> 玉城基文 | N2: ='精算書（交通費）'!S47 -> 4380 | P2: 課対仕入内10%適格 | Q2: ='精算書（交通費）'!A47 -> 電車・バス | S2: =MID(CELL("filename"),FIND("[",CELL("filename"))+1,FIND("]",CELL("filename"))-FIND("[",CELL("filename"))-1) -> 精算書_集（交通費）_玉城基文_202607.xlsx
A3: 交通費 | B3: ='精算書（交通費）'!S4 -> 玉城基文 | C3: ='精算書（交通費）'!N4 -> 1073 | D3: ='精算書（交通費）'!J4 -> カスタマサポートエンジニアリング部 | E3: =MAX('精算書（交通費）'!A:A) -> 46226 | F3: =IF(D3="管理部","",IF(D3="営業部","",IF(D3="取締役会","","製造部門"))) -> 製造部門 | I3: 旅費交通費 | J3: =IF(F3<>"","[製]"&I3,I3) -> [製]旅費交通費 | M3: =B3 -> 玉城基文 | N3: ='精算書（交通費）'!S48 -> 0 | P3: 課対仕入内10%適格 | Q3: ='精算書（交通費）'!A48 -> タクシー | S3: =MID(CELL("filename"),FIND("[",CELL("filename"))+1,FIND("]",CELL("filename"))-FIND("[",CELL("filename"))-1) -> 精算書_集（交通費）_玉城基文_202607.xlsx
A4: 交通費 | B4: ='精算書（交通費）'!S4 -> 玉城基文 | C4: ='精算書（交通費）'!N4 -> 1073 | D4: ='精算書（交通費）'!J4 -> カスタマサポートエンジニアリング部 | E4: =MAX('精算書（交通費）'!A:A) -> 46226 | F4: =IF(D4="管理部","",IF(D4="営業部","",IF(D4="取締役会","","製造部門"))) -> 製造部門 | I4: 交際費 | J4: =IF(F4<>"","[製]"&I4,I4) -> [製]交際費 | M4: =B4 -> 玉城基文 | N4: ='精算書（交通費）'!S49 -> 0 | P4: 課対仕入内10%適格 | Q4: =RIGHT('精算書（交通費）'!L49,6) -> 他接待交際費 | S4: =MID(CELL("filename"),FIND("[",CELL("filename"))+1,FIND("]",CELL("filename"))-FIND("[",CELL("filename"))-1) -> 精算書_集（交通費）_玉城基文_202607.xlsx

Sheet 部門
A1: 部門名称一覧
A2: 部門 名前の定義：部門 | B2: 有効フラグ
B3: 1
A4: 取締役会 | B4: 1
A5: 営業部 | B5: 1
A6: 管理部 | B6: 1
A8: 開発本部 | B8: 1
A9: ソリューション開発部 | B9: 1
A10: プラットフォーム開発部 | B10: 1
A12: カスタマサポートエンジニアリング部 | B12: 1
A14: ソフトウェアサービス部 | B14: 1
